Workbook
Name Lenders: 'Roster & Tables'!$I$2:$I$24
Name SalesRoster: 'Roster & Tables'!$C$2:$C$24
Name Makes: 'Roster & Tables'!$L$2:$L$50
Name Type: 'Roster & Tables'!$M$2:$M$8
Name Percent: 'Roster & Tables'!$K$2:$K$21
Name DriveTrain: 'Roster & Tables'!$N$2:$N$6

Sheet Roster & Tables
C1: Sales People | D1: Phone | E1: Confirmed? | F1: Setup | G1: According To Who | I1: Lenders | K1: Percentage | L1: Makes | M1: Type | N1: DriveTrain | P1: Dealership Passwords
B2: 1 | C2: NATE HARDING | E2: Y | I2: 5th/3rd | K2: 1 | L2: Buick | M2: Sedan | N2: FWD | P2: Type | R2: User Name | T2: Password | V2: Email | X2: Challenge Questions
B3: 2 | C3: IRELAND COMBS | E3: Y | I3: Chase | K3: 0.95 | L3: Cadillac | M3: SUV | N3: RWD | P3: ROUTEONE | R3: NATELAMBRECQUE123 | T3: Routeone123 | V3: nate@justdriveevents.com
B4: 3 | C4: TREVON HALL | E4: Y | I4: GM Fin Ret | K4: 0.9 | L4: Chevy | M4: Truck | N4: AWD | P4: DEALER CONNECT
B5: 4 | C5: CHRIS MARTIN | E5: Y | I5: GM Fin LS | K5: 0.85 | L5: Chrysler | M5: Coupe | N5: 4x4 | P5: COX AUTO | R5: Jurso686 | T5: Blauto1200@$$
B6: 5 | C6: NICK WILEY | E6: Y | I6: KeyBank N.A. | K6: 0.8 | L6: Dodge | M6: Hatch | N6: 4x2 | P6: DL VINS | R6: Jurso02 | T6: Elgin222
B7: 6 | C7: HALEY DELUDE | E7: Y | G7: Team Leader | I7: Ally | K7: 0.75 | L7: Ford | M7: Van | P7: Dealer Policy
B8: 7 | C8: MIKE LASHLEY | E8: Y | I8: Mazda | K8: 0.65 | L8: Honda | M8: Other | P8: SECOND PENCIL
B9: 8 | C9: BRYANT ROGERS | E9: Y | I9: BOA | K9: 0.6 | L9: Hyundai | M9: Convertible
B10: 9 | C10: ABDUL AL TABBAH | E10: Y | I10: Gateway | K10: 0.55 | L10: Jeep | M10: Wagon
B11: 10 | C11: JOSE TORRES | E11: Y | I11: NBT | K11: 0.5 | L11: Kia | P11: KEYTRAK | R11: MIKE BRYANT | T11: 42144
B12: 11 | C12: IGOR PLETNOR | E12: Y | I12: Capital One | K12: 0.45 | L12: Lincoln
B13: 12 | C13: MAYCON MIKE GUIMARAES | E13: Y | G13: F&I Manager | I13: Huntington | K13: 0.4 | L13: Mazda | P13: AM1LEADS.COM | R13: F570 | T13: Nate777
B14: 13 | C14: OSSIE SAMPSON | E14: Y | G14: NATE LABRECQUE | I14: TD Auto | K14: 0.35 | L14: Mitsubishi | P14: JDE HQ
B15: 14 | C15: MAKOTO "TOKYO" MACHO | E15: Y | I15: HANSCOM FED | K15: 0.3 | L15: Nissan | P15: computer password | R15: Hyundai1200$
B16: 15 | C16: BRYAN ROGERS | E16: Y | I16: service cu | K16: 0.25 | L16: Pontiac
E17: Y | I17: CASH | K17: 0.2 | L17: Ram | P17: KEY TRACK ADMIN CODE | R17: jde | T17: 4321
G18: CLOSERS | I18: Wells Fargo | K18: 0.15 | L18: Subaru
G19: MICHAEL BARR | K19: 0.1 | L19: Toyota | P19: GAP | R19: 519
G21: MICHAEL BRYANT | K21: 0.05 | L21: VW | P21: Nate's BL Comp Login | R21: nlabrecque@blautogroup.com | T21: BLag2026$$
C24: HOUSE | G24: 4703324926 | L24: -----------
L25: Acura
C26: Dealer Information | I26: Financial Information | L26: Alfa Romeo | N26: $$ LOANED
C27: Sale Start Date | D27: 46069 | I27: Doc Fees. | L27: Aston Martin
C28: End Date | D28: 46074 | I28: TT&L | L28: Audi
C29: Dealer Name | D29: HONDA CITY | I29: Pack | J29: 0 | L29: Bentley
C30: Franchise | D30: HONDA | I30: JDE PAYOUT | J30: 0.35 | L30: BMW
C31: Street Address | D31: 4950 S PULASKI RD | I31: Tax rate | J31: 0.1025 | L31: Ferrari
C32: City | D32: CHICAGO | L32: Fiat
C33: State | D33: ILLINOIS | L33: Freightliner
C34: Zip | D34: 60632 | L34: Genesis
L35: Infiniti
C36: Marketing Information | I36: Dealership Production (Avg. Per Month) | L36: Jaguar
C37: Direct Mail Title | D37: WIN BIG | I37: Used Vehicle Units | L37: Lamborghini
C38: Direct Mail # | I38: New Vehicle Units | L38: Land Rover
C39: CAP Letter # | I39: Front Gross Per Unit | L39: Lexus | N39: LX, SPORT, EX, EX-L, TOURING, ELITE
C40: Total Sales Days | D40: 6 | I40: Back Gross Per Unit | L40: Lotus
C41: Mail Investment | I41: Marketing $ | L41: Maserati
I42: Traffic Per Day | L42: McLaren
I43: Total Gross Used Car | L43: Mercedes-Benz
...

Sheet INVENTORY
A1: HAT | C1: STATUS | D1: Stock # | E1: Year | F1: Make | G1: Model | H1: Class | I1: Color | J1: Odometer | K1: VIN | L1: Series | M1: Age | N1: Drivetrain Type | O1: J.D. Power Trade In Clean | P1: J.D. Power Retail Clean | Q1: Unit Cost | R1: DIFF | S1: 1.15 | T1: 1.15 | U1: 1.2 | V1: 1.2 | W1: 1.25 | X1: 1.25 | Y1: 1.3 | Z1: 1.3
A2: 1 | B2: TRADE | D2: C20657A | E2: 2023 | F2: HONDA | G2: CR-V | H2: SUV | I2: RADIANT RED | J2: 46053 | K2: 7FARS6H5XPE033768 | L2: SPORT HYBRID | M2: 1 | N2: AWD | O2: 24175 | P2: 27675 | Q2: 20850 | R2: =O2-Q2 -> 3325 | S2: =O2*1.15 -> 27801.25 | T2: =S2-Q2 -> 6951.25 | U2: =O2*1.25 -> 30218.75 | V2: =U2-Q2 -> 9368.75 | W2: =O2*1.4 -> 33845 | X2: =W2-Q2 -> 12995 | Y2: =W2*0.0207 -> 700.5915 | Z2: =Y2-Q2 -> -20149.409 | AF2: =P2-Q2 -> 6825 | AH2: 40895 | AI2: 685
A3: 1 | B3: TRADE | D3: DC20851A | E3: 2018 | F3: HONDA | G3: CIVIC | H3: Sedan | I3: GRAY | J3: 32238 | K3: 2HGFC2F59JH577432 | L3: LX | M3: 1 | N3: FWD | O3: 14550 | P3: 17875 | Q3: 14350 | R3: =O3-Q3 -> 200 | S3: =O3*1.15 -> 16732.5 | T3: =S3-Q3 -> 2382.5 | U3: =O3*1.25 -> 18187.5 | V3: =U3-Q3 -> 3837.5 | W3: =O3*1.4 -> 20370 | X3: =W3-Q3 -> 6020 | Y3: =W3*0.0207 -> 421.659 | Z3: =Y3-Q3 -> -13928.341 | AF3: =P3-Q3 -> 3525 | AH3: 33148 | AI3: 685
A4: 1 | B4: TRADE | D4: C20976A | E4: 2024 | F4: KIA | G4: K5 | H4: Sedan | I4: WHITE | J4: 23982 | K4: 5XXG64J21RG246944 | L4: GT-LINE | M4: 2 | N4: FWD | O4: 23175 | P4: 26175 | Q4: 20000 | R4: =O4-Q4 -> 3175 | S4: =O4*1.15 -> 26651.25 | T4: =S4-Q4 -> 6651.25 | U4: =O4*1.25 -> 28968.75 | V4: =U4-Q4 -> 8968.75 | W4: =O4*1.4 -> 32445 | X4: =W4-Q4 -> 12445 | Y4: =W4*0.0207 -> 671.6115 | Z4: =Y4-Q4 -> -19328.389 | AF4: =P4-Q4 -> 6175 | AH4: 11930 | AI4: 685
A5: 1 | B5: TRADE | D5: C20798A | E5: 2014 | F5: TOYOTA | G5: HIGHLANDER | H5: SUV | I5: BLUE | J5: 113124 | K5: 5TDJKRFH7ES038748 | L5: XLE Premium | M5: 1 | N5: 4WD | O5: 13525 | P5: 15725 | Q5: 13350 | R5: =O5-Q5 -> 175 | S5: =O5*1.15 -> 15553.75 | T5: =S5-Q5 -> 2203.75 | U5: =O5*1.25 -> 16906.25 | V5: =U5-Q5 -> 3556.25 | W5: =O5*1.25 -> 16906.25 | X5: =W5-Q5 -> 3556.25 | Y5: =O5*1.3 -> 17582.5 | Z5: =Y5-Q5 -> 4232.5 | AF5: =P5-Q5 -> 2375 | AH5: 24795 | AI5: 685
A6: 1 | B6: TRADE | D6: DC20964B | E6: 2019 | F6: HONDA | G6: PASSPORT | H6: SUV | I6: WHITE | J6: 109541 | K6: 5FNYF8H50KB014422 | L6: EX-L | M6: 1 | N6: AWD | O6: 16050 | P6: 18250 | Q6: 12350 | R6: =O6-Q6 -> 3700
A7: 1 | B7: TRADE | D7: C20968A | E7: 2015 | F7: TOYOTA | G7: CAMRY | H7: Sedan | I7: SILVER | J7: 133865 | K7: 4T4BF1FK4FR466846 | L7: LE | M7: 1 | O7: 7750 | P7: 11700 | Q7: 6250 | R7: =O7-Q7 -> 1500
A8: 1 | B8: TRADE | D8: C20853A | E8: 2022 | F8: HONDA | G8: PILOT | H8: SUV | I8: GRAY | J8: 35540 | K8: 5FNYF6H83NB077078 | L8: TRAILSPORT | M8: 1 | N8: AWD | O8: 29350 | P8: 31075 | Q8: 29250 | R8: =O8-Q8 -> 100
A9: 1 | B9: TRADE | D9: C20673A | E9: 2012 | F9: FORD | G9: FUSION | H9: Sedan | I9: GRAY | J9: 66828 | K9: 3FAHP0JA4CR337318 | L9: SEL | M9: 1 | O9: 4688 | P9: 8363 | Q9: 3550 | R9: =O9-Q9 -> 1138
A10: 1 | B10: TRADE | D10: C20754A | E10: 2025 | F10: JEEP | G10: COMPASS | H10: SUV | I10: BLACK | J10: 4716 | K10: 3C4NJDBNXST528248 | L10: LAT | M10: 1 | N10: 4WD | O10: 22725 | P10: 29250 | Q10: 22250 | R10: =O10-Q10 -> 475
A11: 1 | B11: TRADE | D11: C20689A | E11: 2020 | F11: JEEP | G11: GRAND CHERO | H11: SUV | I11: BLACK | J11: 64473 | K11: 1C4RJFBG4LC255979 | L11: LIMITED | M11: 1 | N11: 4WD | O11: 18525 | P11: 21475 | Q11: 12250 | R11: =O11-Q11 -> 6275
A12: 1 | B12: TRADE | D12: C20976A | E12: 2024 | F12: KIA | G12: K5 | H12: Sedan | I12: WHITE | J12: 23982 | K12: 5XXG64J21RG246944 | L12: GT-LINE | M12: 1 | N12: FWD | O12: 23750 | P12: 26825 | Q12: 21350 | R12: =O12-Q12 -> 2400
A13: 2 | D13: P6234 | E13: 2023 | F13: Acura | G13: MDX | H13: SUV | I13: Black | J13: 40771 | K13: 5J8YE1H83PL014344 | L13: Advance | M13: 83 | N13: AWD | O13: 40850 | P13: 44575 | Q13: 40472 | R13: =O13-Q13 -> 378 | S13: =O13*1.15 -> 46977.5 | T13: =S13-Q13 -> 6505.5 | U13: =O13*1.25 -> 51062.5 | V13: =U13-Q13 -> 10590.5 | W13: =O13*1.25 -> 51062.5 | X13: =W13-Q13 -> 10590.5 | Y13: =O13*1.3 -> 53105 | Z13: =Y13-Q13 -> 12633
A14: 3 | D14: C20912A | E14: 2024 | F14: Acura | G14: Integra | H14: Sedan | I14: Gray | J14: 28823 | K14: 19UDE4H25RA027106 | L14: Base | M14: 8 | N14: FWD | O14: 21925 | P14: 26000 | Q14: 22229 | R14: =O14-Q14 -> -304 | S14: =O14*1.15 -> 25213.75 | T14: =S14-Q14 -> 2984.75 | U14: =O14*1.25 -> 27406.25 | V14: =U14-Q14 -> 5177.25 | W14: =O14*1.25 -> 27406.25 | X14: =W14-Q14 -> 5177.25 | Y14: =O14*1.3 -> 28502.5 | Z14: =Y14-Q14 -> 6273.5 | AH14: 15576 | AI14: 685
A15: 5 | D15: P6284 | E15: 2021 | F15: Honda | G15: Civic | H15: Sedan | I15: Silver | J15: 36102 | K15: 2HGFC2F67MH539193 | L15: LX | M15: 9 | N15: FWD | O15: 16325 | P15: 19175 | Q15: 19278 | R15: =O15-Q15 -> -2953 | S15: =O15*1.15 -> 18773.75 | T15: =S15-Q15 -> -504.25 | U15: =O15*1.25 -> 20406.25 | V15: =U15-Q15 -> 1128.25 | W15: =O15*1.25 -> 20406.25 | X15: =W15-Q15 -> 1128.25 | Y15: =O15*1.3 -> 21222.5 | Z15: =Y15-Q15 -> 1944.5 | AH15: 23802 | AI15: 685
A16: 6 | D16: C20520A | E16: 2021 | F16: Honda | G16: Passport | H16: SUV | I16: Platinum White | J16: 71769 | K16: 5FNYF8H08MB003790 | L16: Elite | M16: 8 | N16: AWD | O16: 25200 | P16: 27600 | Q16: 25751 | R16: =O16-Q16 -> -551 | T16: =S16-Q16 -> -25751 | V16: =U16-Q16 -> -25751 | X16: =W16-Q16 -> -25751 | Z16: =Y16-Q16 -> -25751
A17: 7 | D17: P6282 | E17: 2023 | F17: GMC | G17: Acadia | H17: SUV | I17: Volcanic Red Tintcoat | J17: 60970 | K17: 1GKKNUL43PZ234420 | L17: SLT | M17: 10 | N17: AWD | O17: 23200 | P17: 25500 | Q17: 24541 | R17: =O17-Q17 -> -1341 | S17: =O17*1.15 -> 26680 | T17: =S17-Q17 -> 2139 | U17: =O17*1.25 -> 29000 | V17: =U17-Q17 -> 4459 | W17: =O17*1.25 -> 29000 | X17: =W17-Q17 -> 4459 | Y17: =O17*1.3 -> 30160 | Z17: =Y17-Q17 -> 5619 | AF17: =P17-Q17 -> 959 | AH17: 33702 | AI17: 685
A18: 8 | D18: XP6289 | E18: 2022 | F18: Ford | G18: Escape | H18: SUV | I18: Agate Black Metallic | J18: 53251 | K18: 1FMCU0G63NUB97494 | L18: SE | M18: 3 | N18: FWD | O18: 14875 | P18: 18900 | Q18: 17343 | R18: =O18-Q18 -> -2468 | S18: =O18*1.15 -> 17106.25 | T18: =S18-Q18 -> -236.75 | U18: =O18*1.25 -> 18593.75 | V18: =U18-Q18 -> 1250.75 | W18: =O18*1.25 -> 18593.75 | X18: =W18-Q18 -> 1250.75 | Y18: =O18*1.3 -> 19337.5 | Z18: =Y18-Q18 -> 1994.5 | AH18: 9599 | AI18: 685
A19: 10 | D19: P6286 | E19: 2023 | F19: Honda | G19: HR-V | H19: Hatch | I19: Black | J19: 32113 | K19: 3CZRZ1H35PM709722 | L19: LX | M19: 9 | N19: FWD | O19: 19600 | P19: 21725 | Q19: 22313 | R19: =O19-Q19 -> -2713 | S19: =O19*1.15 -> 22540 | T19: =S19-Q19 -> 227 | U19: =O19*1.25 -> 24500 | V19: =U19-Q19 -> 2187 | W19: =O19*1.25 -> 24500 | X19: =W19-Q19 -> 2187 | Y19: =O19*1.3 -> 25480 | Z19: =Y19-Q19 -> 3167 | AF19: =P19-Q19 -> -588 | AH19: 23399 | AI19: 685
A20: 11 | D20: C20694A | E20: 2010 | F20: Honda | G20: CR-V | H20: SUV | I20: Silver | J20: 189287 | K20: JHLRE3H53AC005299 | L20: EX | M20: 55 | N20: FWD | O20: 4575 | P20: 6725 | Q20: 5993 | R20: =O20-Q20 -> -1418 | S20: =O20*1.15 -> 5261.25 | T20: =S20-Q20 -> -731.75 | U20: =O20*1.25 -> 5718.75 | V20: =U20-Q20 -> -274.25 | W20: =O20*1.25 -> 5718.75 | X20: =W20-Q20 -> -274.25 | Y20: =O20*1.3 -> 5947.5 | Z20: =Y20-Q20 -> -45.5 | AF20: =P20-Q20 -> 732 | AH20: 22898 | AI20: 685
A21: 12 | D21: P6268 | E21: 2024 | F21: Mazda | G21: Mazda3 | H21: Sedan | I21: Jet Black Mica | J21: 53095 | K21: JM1BPAKM5R1700968 | L21: 2.5 S Select Sport | M21: 33 | N21: FWD | O21: 16975 | P21: 20050 | Q21: 19275 | R21: =O21-Q21 -> -2300 | S21: =O21*1.15 -> 19521.25 | T21: =S21-Q21 -> 246.25 | U21: =O21*1.25 -> 21218.75 | V21: =U21-Q21 -> 1943.75 | W21: =O21*1.25 -> 21218.75 | X21: =W21-Q21 -> 1943.75 | Y21: =O21*1.3 -> 22067.5 | Z21: =Y21-Q21 -> 2792.5 | AH21: 33621 | AI21: 685
A22: 13 | D22: XP6248 | E22: 2024 | F22: Ford | G22: Escape | H22: SUV | I22: Gray Metallic | J22: 8482 | K22: 1FMCU9GN9RUB62427 | L22: Active | M22: 62 | N22: AWD | O22: 21200 | P22: 26075 | Q22: 25102 | R22: =O22-Q22 -> -3902 | S22: =O22*1.15 -> 24380 | T22: =S22-Q22 -> -722 | U22: =O22*1.25 -> 26500 | V22: =U22-Q22 -> 1398 | W22: =O22*1.25 -> 26500 | X22: =W22-Q22 -> 1398 | Y22: =O22*1.3 -> 27560 | Z22: =Y22-Q22 -> 2458 | AH22: 22049 | AI22: 685
A23: 14 | D23: C20485A | E23: 2024 | F23: Honda | G23: Civic Si | H23: Sedan | I23: Crystal Black Pearl | J23: 12037 | K23: 2HGFE1E53RH475240 | L23: Base | M23: 93 | N23: FWD | O23: 26600 | P23: 29475 | Q23: 30703 | R23: =O23-Q23 -> -4103 | S23: =O23*1.15 -> 30590 | T23: =S23-Q23 -> -113 | U23: =O23*1.25 -> 33250 | V23: =U23-Q23 -> 2547 | W23: =O23*1.25 -> 33250 | X23: =W23-Q23 -> 2547 | Y23: =O23*1.3 -> 34580 | Z23: =Y23-Q23 -> 3877 | AF23: =P23-Q23 -> -1228 | AH23: 31576 | AI23: 685
A24: 16 | D24: P6264 | E24: 2024 | F24: GMC | G24: Terrain | H24: SUV | I24: Ebony Twilight Metallic | J24: 45361 | K24: 3GKALTEGXRL372517 | L24: SLE | M24: 34 | N24: AWD | O24: 19800 | P24: 23500 | Q24: 22011 | R24: =O24-Q24 -> -2211 | S24: =O24*1.15 -> 22770 | T24: =S24-Q24 -> 759 | U24: =O24*1.25 -> 24750 | V24: =U24-Q24 -> 2739 | W24: =O24*1.4 -> 27720 | X24: =W24-Q24 -> 5709 | Y24: =W24*0.0207 -> 573.804 | Z24: =Y24-Q24 -> -21437.196 | AF24: =P24-Q24 -> 1489 | AH24: 32137 | AI24: 685
A25: 18 | D25: P6275 | E25: 2025 | F25: Mitsubishi | G25: Outlander | H25: SUV | I25: Black | J25: 17786 | K25: JA4J4VA83SZ032749 | L25: SE | M25: 19 | N25: 4WD | O25: 25600 | P25: 30500 | Q25: 27243 | R25: =O25-Q25 -> -1643 | S25: =O25*1.15 -> 29440 | T25: =S25-Q25 -> 2197 | U25: =O25*1.25 -> 32000 | V25: =U25-Q25 -> 4757 | W25: =O25*1.4 -> 35840 | X25: =W25-Q25 -> 8597 | Y25: =W25*0.0207 -> 741.888 | Z25: =Y25-Q25 -> -26501.112 | AF25: =P25-Q25 -> 3257 | AH25: 48869 | AI25: 685
A26: 20 | D26: P6227A | E26: 2015 | F26: Lincoln | G26: MKT | H26: SUV | I26: Ruby Red Metallic | J26: 101181 | K26: 2LMHJ5AT5FBL03014 | L26: EcoBoost | M26: 74 | N26: AWD | O26: 7575 | P26: 10550 | Q26: 7848 | R26: =O26-Q26 -> -273 | S26: =O26*1.15 -> 8711.25 | T26: =S26-Q26 -> 863.25 | U26: =O26*1.25 -> 9468.75 | V26: =U26-Q26 -> 1620.75 | W26: =O26*1.25 -> 9468.75 | X26: =W26-Q26 -> 1620.75 | Y26: =O26*1.3 -> 9847.5 | Z26: =Y26-Q26 -> 1999.5 | AH26: 15858 | AI26: 685
A27: 21 | D27: C20876A | E27: 2024 | F27: Honda | G27: HR-V | H27: Hatch | I27: Crystal Black Pearl | J27: 22362 | K27: 3CZRZ1H51RM730619 | L27: Sport | M27: 32 | N27: FWD | O27: 22025 | P27: 25850 | Q27: 23960 | R27: =O27-Q27 -> -1935 | S27: =O27*1.15 -> 25328.75 | T27: =S27-Q27 -> 1368.75 | U27: =O27*1.25 -> 27531.25 | V27: =U27-Q27 -> 3571.25 | W27: =O27*1.25 -> 27531.25 | X27: =W27-Q27 -> 3571.25 | Y27: =O27*1.3 -> 28632.5 | Z27: =Y27-Q27 -> 4672.5 | AH27: 25933 | AI27: 685
A28: 22 | D28: DC20644A | E28: 2019 | F28: Honda | G28: Insight | H28: SUV | I28: Crystal Black Pearl | J28: 145259 | K28: 19XZE4F97KE033674 | L28: Touring | M28: 60 | N28: FWD | O28: 10525 | P28: 15725 | Q28: 11078 | R28: =O28-Q28 -> -553 | S28: =O28*1.15 -> 12103.75 | T28: =S28-Q28 -> 1025.75 | U28: =O28*1.25 -> 13156.25 | V28: =U28-Q28 -> 2078.25 | W28: =O28*1.25 -> 13156.25 | X28: =W28-Q28 -> 2078.25 | Y28: =O28*1.3 -> 13682.5 | Z28: =Y28-Q28 -> 2604.5 | AH28: 27939 | AI28: 685
A29: 23 | D29: C20844A | E29: 2024 | F29: Honda | G29: Accord | H29: Sedan | I29: Gray Metallic | J29: 9006 | K29: 1HGCY1F28RA063666 | L29: LX | M29: 65 | N29: FWD | O29: 23425 | P29: 27600 | Q29: 23945 | R29: =O29-Q29 -> -520 | S29: =O29*1.15 -> 26938.75 | T29: =S29-Q29 -> 2993.75 | U29: =O29*1.25 -> 29281.25 | V29: =U29-Q29 -> 5336.25 | W29: =O29*1.25 -> 29281.25 | X29: =W29-Q29 -> 5336.25 | Y29: =O29*1.3 -> 30452.5 | Z29: =Y29-Q29 -> 6507.5 | AH29: 30441 | AI29: 685
A30: 24 | D30: P6255 | E30: 2023 | F30: Honda | G30: Odyssey | H30: Van | I30: Modern Steel Metallic | J30: 33823 | K30: 5FNRL6H68PB017117 | L30: EX-L | M30: 58 | N30: FWD | O30: 31175 | P30: 34050 | Q30: 32219 | R30: =O30-Q30 -> -1044 | S30: =O30*1.15 -> 35851.25 | T30: =S30-Q30 -> 3632.25 | U30: =O30*1.25 -> 38968.75 | V30: =U30-Q30 -> 6749.75 | W30: =O30*1.25 -> 38968.75 | X30: =W30-Q30 -> 6749.75 | Y30: =O30*1.3 -> 40527.5 | Z30: =Y30-Q30 -> 8308.5
A31: 25 | D31: RTC20458 | E31: 2025 | F31: Honda | G31: Accord | H31: Sedan | I31: Radiant Red Metallic | J31: 1010 | K31: 1HGCY1F40SA051227 | L31: SE | M31: 38 | N31: FWD | O31: 26175 | P31: 29050 | Q31: 28805 | R31: =O31-Q31 -> -2630 | S31: =O31*1.15 -> 30101.25 | T31: =S31-Q31 -> 1296.25 | U31: =O31*1.25 -> 32718.75 | V31: =U31-Q31 -> 3913.75 | W31: =O31*1.25 -> 32718.75 | X31: =W31-Q31 -> 3913.75 | Y31: =O31*1.3 -> 34027.5 | Z31: =Y31-Q31 -> 5222.5
A32: 25 | D32: P6261 | E32: 2020 | F32: Honda | G32: Civic | H32: Sedan | I32: Black | J32: 61463 | K32: 19XFC1F76LE212750 | L32: EX-L | M32: 37 | N32: FWD | O32: 17300 | P32: 20300 | Q32: 22730 | R32: =O32-Q32 -> -5430 | S32: =O32*1.15 -> 19895 | T32: =S32-Q32 -> -2835 | U32: =O32*1.25 -> 21625 | V32: =U32-Q32 -> -1105 | W32: =O32*1.25 -> 21625 | X32: =W32-Q32 -> -1105 | Y32: =O32*1.3 -> 22490 | Z32: =Y32-Q32 -> -240 | AF32: =P32-Q32 -> -2430 | AH32: 16144 | AI32: 685
A33: 27 | D33: DC20507A | E33: 2023 | F33: Honda | G33: Accord | H33: Sedan | I33: Lunar Silver Metallic | J33: 11732 | K33: 1HGCY1F31PA054863 | L33: EX | M33: 36 | N33: FWD | O33: 24200 | P33: 26925 | Q33: 25817 | R33: =O33-Q33 -> -1617 | S33: =O33*1.15 -> 27830 | T33: =S33-Q33 -> 2013 | U33: =O33*1.25 -> 30250 | V33: =U33-Q33 -> 4433 | W33: =O33*1.25 -> 30250 | X33: =W33-Q33 -> 4433 | Y33: =O33*1.3 -> 31460 | Z33: =Y33-Q33 -> 5643 | AH33: 21709 | AI33: 685
A34: 28 | D34: P6283 | E34: 2024 | F34: Honda | G34: CR-V | H34: SUV | I34: Black | J34: 59737 | K34: 2HKRS4H49RH475291 | L34: EX | M34: 9 | N34: AWD | O34: 25825 | P34: 28950 | Q34: 27270 | R34: =O34-Q34 -> -1445 | T34: =S34-Q34 -> -27270 | V34: =U34-Q34 -> -27270 | X34: =W34-Q34 -> -27270 | Z34: =Y34-Q34 -> -27270
A35: 29 | D35: C20878A | E35: 2015 | F35: Honda | G35: Accord | H35: Sedan | I35: Black | J35: 141213 | K35: 1HGCR2F35FA245137 | L35: LX | M35: 15 | N35: FWD | O35: 6450 | P35: 9500 | Q35: 8676 | R35: =O35-Q35 -> -2226 | S35: =O35*1.15 -> 7417.5 | T35: =S35-Q35 -> -1258.5 | U35: =O35*1.25 -> 8062.5 | V35: =U35-Q35 -> -613.5 | W35: =O35*1.4 -> 9030 | X35: =W35-Q35 -> 354 | Y35: =W35*0.0207 -> 186.921 | Z35: =Y35-Q35 -> -8489.079 | AF35: =P35-Q35 -> 824 | AH35: 16672 | AI35: 685
A36: 30 | D36: XP6258 | E36: 2024 | F36: Toyota | G36: Corolla | H36: Sedan | I36: Silver | J36: 31393 | K36: 5YFB4MDE6RP191601 | L36: LE | M36: 38 | N36: FWD | O36: 17775 | P36: 21175 | Q36: 20672 | R36: =O36-Q36 -> -2897 | S36: =O36*1.15 -> 20441.25 | T36: =S36-Q36 -> -230.75 | U36: =O36*1.25 -> 22218.75 | V36: =U36-Q36 -> 1546.75 | W36: =O36*1.25 -> 22218.75 | X36: =W36-Q36 -> 1546.75 | Y36: =O36*1.3 -> 23107.5 | Z36: =Y36-Q36 -> 2435.5 | AF36: =P36-Q36 -> 503 | AH36: 22527 | AI36: 685
A37: 31 | D37: C20752A | E37: 2025 | F37: Honda | G37: HR-V | H37: Hatch | I37: Modern Steel Metallic | J37: 10095 | K37: 3CZRZ1H34SM737312 | L37: LX | M37: 46 | N37: FWD | O37: 21925 | P37: 26075 | Q37: 22915 | R37: =O37-Q37 -> -990 | S37: =O37*1.15 -> 25213.75 | T37: =S37-Q37 -> 2298.75 | U37: =O37*1.25 -> 27406.25 | V37: =U37-Q37 -> 4491.25 | W37: =O37*1.25 -> 27406.25 | X37: =W37-Q37 -> 4491.25 | Y37: =O37*1.3 -> 28502.5 | Z37: =Y37-Q37 -> 5587.5 | AH37: 40654 | AI37: 685
A38: 32 | D38: P6252 | E38: 2019 | F38: Honda | G38: CR-V | H38: SUV | I38: Blue | J38: 61539 | K38: 7FARW1H83KE031144 | L38: EX-L | M38: 60 | N38: FWD | O38: 19475 | P38: 23350 | Q38: 20396 | R38: =O38-Q38 -> -921 | S38: =O38*1.15 -> 22396.25 | T38: =S38-Q38 -> 2000.25 | U38: =O38*1.25 -> 24343.75 | V38: =U38-Q38 -> 3947.75 | W38: =O38*1.25 -> 24343.75 | X38: =W38-Q38 -> 3947.75 | Y38: =O38*1.3 -> 25317.5 | Z38: =Y38-Q38 -> 4921.5
A39: 33 | D39: C20867A | E39: 2022 | F39: Honda | G39: Pilot | H39: SUV | I39: Obsidian Blue | J39: 34571 | K39: 5FNYF5H52NB009953 | L39: EX-L | M39: 59 | N39: FWD | O39: 27250 | P39: 28925 | Q39: 28286 | R39: =O39-Q39 -> -1036 | S39: =O39*1.15 -> 31337.5 | T39: =S39-Q39 -> 3051.5 | U39: =O39*1.25 -> 34062.5 | V39: =U39-Q39 -> 5776.5 | W39: =O39*1.25 -> 34062.5 | X39: =W39-Q39 -> 5776.5 | Y39: =O39*1.3 -> 35425 | Z39: =Y39-Q39 -> 7139 | AF39: =P39-Q39 -> 639 | AH39: 33610 | AI39: 685
A40: 34 | D40: P6267 | E40: 2023 | F40: Nissan | G40: Altima | H40: Sedan | I40: Super Black Clearcoat | J40: 59123 | K40: 1N4BL4CV4PN357702 | L40: 2.5 SR | M40: 34 | N40: FWD | O40: 17550 | P40: 20075 | Q40: 19712 | R40: =O40-Q40 -> -2162 | S40: =O40*1.15 -> 20182.5 | T40: =S40-Q40 -> 470.5 | U40: =O40*1.25 -> 21937.5 | V40: =U40-Q40 -> 2225.5 | W40: =O40*1.4 -> 24570 | X40: =W40-Q40 -> 4858 | Y40: =W40*0.0207 -> 508.599 | Z40: =Y40-Q40 -> -19203.401 | AH40: 15295 | AI40: 685
...

Sheet DEAL LOG
E1: $$? | G1: DEAL# | H1: STOCK# | I1: CUSTOMER | J1: WORK DONE | K1: NEW/USED | L1: YEAR | M1: MAKE | N1: MODEL | O1: COST | P1: AGE | Q1: YEAR | R1: MAKE | S1: MODEL | T1: MILES | U1: ACV | V1: PAYOFF | W1: SALESPERSON | X1: 2ND SALESPERSON | Y1: FRONT GROSS | Z1: LENDER | AA1: RATE | AB1: RESERVE | AC1: WARRANTY | AD1: AFT 1 | AE1: GAP | AF1: F&I TOOLS | AG1: TOTAL GROSS | AH1: DAILY GROSS | AI1: ADD GROSS | AJ1: DLR GROSS | AK1: JDE PAY | AL1: NOTES
F2: 1 | G2: TODAY'S DATE | I2: 2/16/26-2/21/26 | K2: UPS | AA2: =SUM(M2:Z2) -> 0 | AM2: DELIVERY % | AN2: FRONT PVR | AO2: BACK PVR | AP2: TOT PVR
F3: 1 | G3: DEALERSHIP | I3: HONDA CITY | K3: NEW | N3: 0 | O3: 0 | Q3: 0 | R3: 0 | S3: 2 | AA3: =SUM(M3:Z3) -> 2 | AC3: CLOSING | AL3: Sale Log | AM3: =(AA4+AA3)/AA2 -> #DIV/0! | AN3: =Y118/AB4 -> #VALUE! | AO3: =AF119/AB4 -> #VALUE! | AP3: =AN3+AO3 -> #VALUE!
K4: USED | AA4: =SUM(M4:Z4) -> 0 | AB4: =AA3+AA4 -> 2 | AC4: =AB4/AA2 -> #DIV/0!
M5: =M3+M4 -> #VALUE! | N5: =N3+N4 -> #VALUE! | O5: =O3+O4 -> #VALUE! | Q5: =Q3+Q4 -> #VALUE! | R5: =R3+R4 -> #VALUE! | S5: =S3+S4 -> #VALUE! | T5: =T3+T4 -> 0 | U5: =U3+U4 -> 0 | W5: =W3+W4 -> 0 | X5: =X3+X4 -> 0 | Y5: =Y3+Y4 -> 0 | Z5: =Z3+Z4 -> 0
AA6: =SUM(M6:Z6) -> 0
E7: $$? | G7: STORE | H7: STOCK# | I7: CUSTOMER | J7: ZIPCODE | K7: NEW/USED | L7: YEAR | M7: MAKE | N7: MODEL | O7: COST | P7: AGE | Q7: YEAR | R7: MAKE | S7: MODEL | T7: MILES | U7: ACV | V7: PAYOFF | W7: SALESPERSON | X7: 2ND SALESPERSON | Y7: FRONT GROSS | Z7: LENDER | AA7: RATE | AB7: RESERVE | AC7: WARRANTY | AD7: AFT 1 | AE7: GAP | AF7: FI TOTALS | AG7: TOTAL GROSS | AH7: DAILY GROSS | AI7: HOLDBACK | AJ7: DLR GROSS | AK7: JDE PAY | AL7: NOTES
C10: 1 | D10: 1 | H10: C20931A | I10: ESCALONA | J10: 60443 | K10: Used | L10: 2025 | M10: HONDA | N10: HR-V | O10: 24677 | P10: 7 | W10: BRYAN ROGERS | X10: NICK WILEY | Y10: 5113.2 | Z10: HONDA | AA10: 13.74 | AB10: 1092.42 | AC10: 1837 | AE10: 762 | AF10: =SUM(AB10:AE10) -> 3691.42 | AG10: =Y10+AF10 -> 8804.62
C11: 2 | D11: 2 | H11: RTC19587A | I11: NINO BARON | J11: 60153 | K11: Used | L11: 2025 | M11: HONDA | N11: CR-V | O11: 28686.44 | P11: 32 | W11: HOUSE | Y11: 4237.56 | Z11: HONDA | AA11: 7.29 | AB11: 1709.32 | AC11: 2459 | AD11: 1488 | AF11: =SUM(AB11:AE11) -> 5656.32 | AG11: =Y11+AF11 -> 9893.88
C12: 3 | D12: 3 | H12: C20657 | I12: RAMOS RAMOS | J12: 60625 | K12: New | L12: 2026 | M12: HONDA | N12: CR-V | O12: 38663 | P12: 165 | Q12: 2023 | R12: HONDA | S12: CRV | T12: 46053 | U12: 19500 | V12: 25608 | W12: HOUSE | Y12: 2247.31 | Z12: CAP 1 | AA12: 12.65 | AB12: 2822.92 | AE12: 631 | AF12: =SUM(AB12:AE12) -> 3453.92 | AG12: =Y12+AF12 -> 5701.23 | AI12: 785.1 | AL12: 785.10 HB
AF13: =SUM(AB13:AE13) -> 0 | AG13: =Y13+AF13 -> 0 | AH13: =SUM(AG10:AG12) -> 24399.73
C14: 1 | D14: 4 | H14: C20630A | I14: TOVAR | J14: 60609 | K14: Used | L14: 2021 | M14: MAZDA | N14: CX5 | O14: 19203 | P14: 48 | Q14: 2005 | R14: CHRYSLER | S14: PACIFICA | U14: 500 | W14: CHRIS MARTIN | Y14: 3175.92 | Z14: GLOBAL | AA14: 26.2 | AB14: 386.24 | AC14: 1328.24 | AF14: =SUM(AB14:AE14) -> 1714.48 | AG14: =Y14+AF14 -> 4890.4
C15: 2 | D15: 5 | H15: C20879 | I15: DIAZ | J15: 60652 | K15: New | L15: 2026 | M15: HONDA | N15: CIVIC | O15: 24757 | P15: 57 | W15: JOSE TORRES | Y15: 5723.22 | Z15: CHASE | AA15: 7.34 | AB15: 370.99 | AC15: 1687 | AF15: =SUM(AB15:AE15) -> 2057.99 | AG15: =Y15+AF15 -> 7781.21 | AI15: 491.9 | AL15: 491.90 HB
C16: 3 | D16: 6 | H16: DC20851 | I16: CHILE | J16: 60653 | K16: New | L16: 2026 | M16: HONDA | N16: HR-V | O16: 26549 | P16: 45 | Q16: 2018 | R16: HONDA | S16: CIVIC | T16: 32238 | U16: 13000 | V16: 18607 | W16: MAYCON MIKE GUIMARAES | Y16: 0 | Z16: HONDA | AA16: 4.49 | AB16: 200 | AF16: =SUM(AB16:AE16) -> 200 | AG16: =Y16+AF16 -> 200
C17: 4 | D17: 7 | H17: C20535 | I17: PARRA | J17: 60623 | K17: New | L17: 2025 | M17: HONDA | N17: PILOT | O17: 48573.99 | P17: 201 | W17: HOUSE | Y17: 0 | Z17: ALLY | AA17: LS | AB17: 2908.92 | AC17: 622 | AF17: =SUM(AB17:AE17) -> 3530.92 | AG17: =Y17+AF17 -> 3530.92 | AI17: 997.1 | AL17: 997.10 HB
AG18: =Y18+AF18 -> 0 | AH18: =SUM(AG14:AG17) -> 16402.53
D19: 8 | H19: C20754 | I19: MORENO | J19: 60804 | K19: New | L19: 2026 | M19: HONDA | N19: CR-V | O19: 39583.3 | P19: 125 | Q19: 2025 | R19: JEEP | S19: COMPASS | T19: 4716 | U19: 21000 | V19: 29950 | W19: JOSE TORRES | X19: OSSIE SAMPSON | Y19: 4459.53 | Z19: HONDA | AA19: 7.89 | AB19: 3995.46 | AC19: 5910 | AE19: 681 | AF19: =SUM(AB19:AE19) -> 10586.46 | AG19: =Y19+AF19 -> 15045.99 | AI19: 804.5 | AL19: AVP CREDITED TO BACK END
D20: 9 | H20: XP6290 | I20: EARL | J20: 60609 | K20: Used | L20: 2021 | M20: HYUNDAI | N20: TUCSON | O20: 19141.9 | P20: 6 | W20: MIKE LASHLEY | Y20: 2000 | Z20: CHASE | AA20: 10.04 | AB20: 1215.91 | AC20: 697 | AF20: =SUM(AB20:AE20) -> 1912.91 | AG20: =Y20+AF20 -> 3912.91
D21: 10 | H21: C20944 | I21: MORALES | J21: 60629 | K21: New | L21: 2026 | M21: HONDA | N21: CIVIC | O21: 24852.81 | P21: 19 | W21: HOUSE | Y21: 5562.42 | Z21: HONDA | AA21: 7.64 | AB21: 2458.89 | AC21: 4159 | AE21: 376 | AF21: =SUM(AB21:AE21) -> 6993.89 | AG21: =Y21+AF21 -> 12556.31 | AI21: 493.9 | AL21: 493.90 HB
D22: 11 | H22: C20699 | I22: PULIDO | J22: 60501 | K22: New | L22: 2025 | M22: HONDA | N22: PILOT | O22: 48038 | P22: 125 | W22: BRYAN ROGERS | Y22: 9464.81 | Z22: HONDA | AA22: 7.64 | AB22: 4518.99 | AC22: 3885 | AD22: 2954 | AE22: 681 | AF22: =SUM(AB22:AE22) -> 12038.99 | AG22: =Y22+AF22 -> 21503.8 | AI22: 1030 | AL22: 1030 HB
D23: 12 | H23: C20911 | I23: TELLEZ | J23: 60632 | K23: New | L23: 2026 | M23: HONDA | N23: HR-V | O23: 28022 | P23: 30 | Q23: 2004 | R23: NISSAN | S23: QUEST | T23: 59954 | U23: 500 | W23: ABDUL AL TABBAH | Y23: 0 | Z23: HONDA | AA23: 7.29 | AB23: 1537.38 | AD23: RO | AF23: =SUM(AB23:AE23) -> 1537.38 | AG23: =Y23+AF23 -> 1537.38 | AI23: 560 | AL23: 560 HB
AF24: =SUM(AB24:AE24) -> 0 | AG24: =Y24+AF24 -> 0 | AH24: =SUM(AG19:AG23) -> 54556.39
C25: 1 | D25: 13 | H25: C20976 | I25: DELATORRE | J25: 60632 | K25: New | L25: 2026 | M25: HONDA | N25: CR-V | O25: 37266.23 | P25: 7 | Q25: 2024 | R25: KIA | S25: K5 | T25: 23982 | U25: 22000 | W25: NICK WILEY | X25: JOSE TORRES | Y25: 4589.8 | Z25: HONDA | AA25: 7.64 | AB25: 3100.86 | AC25: 3545 | AE25: 681 | AF25: =SUM(AB25:AE25) -> 7326.86 | AG25: =Y25+AF25 -> 11916.66 | AI25: 751.7 | AL25: 751.70 HB
C26: 2 | D26: 14 | H26: C20540A | I26: DEER/PHILLIPS | J26: 60609 | K26: Used | L26: 2022 | M26: HONDA | N26: HR-V | O26: 21072.39 | P26: 65 | W26: JOSE TORRES | X26: NICK WILEY | Y26: 2157 | Z26: WFDS | AA26: 10.24 | AB26: 1473.06 | AC26: 1219 | AF26: =SUM(AB26:AE26) -> 2692.06 | AG26: =Y26+AF26 -> 4849.06
C27: 3 | D27: 15 | H27: C20237A | I27: MONDRAGON | J27: 60623 | K27: Used | L27: 2023 | M27: SUBARU | N27: OUTBACK | O27: 25965.69 | P27: 89 | Q27: 2012 | R27: HYUNDAI | S27: ACCENT | T27: 144000 | U27: 500 | W27: BRYAN ROGERS | Y27: 3758.31 | Z27: WFDS | AA27: 11.74 | AB27: 1695 | AE27: 681 | AF27: =SUM(AB27:AE27) -> 2376 | AG27: =Y27+AF27 -> 6134.31
C28: 4 | D28: 16 | H28: C20935 | I28: BAHENA | J28: 60623 | K28: New | L28: 2026 | M28: HONDA | N28: CIVIC | O28: 24852 | P28: 21 | W28: HOUSE | Y28: 3826.42 | Z28: CAP 1 | AA28: 11.95 | AB28: 1684.62 | AC28: 2691 | AE28: 681 | AF28: =SUM(AB28:AE28) -> 5056.62 | AG28: =Y28+AF28 -> 8883.04 | AI28: 493.9 | AL28: 493.90 HB
C29: 5 | D29: 17 | H29: C20654A | I29: MONDRAGON | J29: 60623 | K29: Used | L29: 2022 | M29: CHEVY | N29: 1500 | O29: 39338 | P29: 88 | Q29: 1999 | R29: DODGE | S29: DURANGO | U29: 1 | W29: BRYAN ROGERS | Y29: 6061.7 | Z29: CAP 1 | AA29: 13.26 | AB29: 241.5 | AC29: 1137 | AF29: =SUM(AB29:AE29) -> 1378.5 | AG29: =Y29+AF29 -> 7440.2
C30: 6 | D30: 18 | H30: C20340 | I30: ROJAS AGUDELO | J30: 60632 | K30: New | L30: 2026 | M30: HONDA | N30: CRV | O30: 32453 | P30: 248 | W30: ABDUL AL TABBAH | X30: JOSE TORRES | Y30: 0 | Z30: HONDA | AA30: 5.99 | AB30: 200 | AE30: 367 | AF30: =SUM(AB30:AE30) -> 567 | AG30: =Y30+AF30 -> 567 | AI30: 648.4 | AL30: 648.40 HB
AF31: =SUM(AB31:AE31) -> 0 | AG31: =Y31+AF31 -> 0 | AH31: =SUM(AG25:AG30) -> 39790.27
C32: 1 | D32: 19 | H32: C20885 | I32: CORTEZ | J32: 60634 | K32: New | L32: 2026 | M32: HONDA | N32: CIVIC | O32: 25190 | P32: 56 | W32: HOUSE | Y32: 0 | Z32: ALLY | AA32: 8.99 | AB32: 0 | AE32: 0 | AF32: =SUM(AB32:AE32) -> 0 | AG32: =Y32+AF32 -> 0 | AI32: 501
C33: 2 | D33: 20 | H33: C20928 | I33: CASTRO FIGUEROA | J33: 60609 | K33: New | L33: 2026 | M33: HONDA | N33: CIVIC | O33: 30352 | P33: 23 | W33: HOUSE | Y33: 2319.19 | Z33: CAP 1 | AA33: 11.01 | AB33: 1644.64 | AF33: =SUM(AB33:AE33) -> 1644.64 | AG33: =Y33+AF33 -> 3963.83 | AI33: 611.9
C34: 3 | D34: 21 | H34: C20673 | I34: DITTMANN | J34: 60603 | K34: New | L34: 2026 | M34: HONDA | N34: HR-V | O34: 29997 | P34: 151 | Q34: 2012 | R34: FORD | S34: FUSION | T34: 66828 | U34: 3000 | V34: 0 | W34: BRYANT ROGERS | X34: BRYAN ROGERS | Y34: 6124.05 | Z34: HONDA | AA34: 2.49 | AB34: 100 | AC34: 1647 | AF34: =SUM(AB34:AE34) -> 1747 | AG34: =Y34+AF34 -> 7871.05 | AI34: 599.1
C35: 4 | D35: 22 | H35: C20926 | I35: ALONSO HERRERA | J35: 60636 | K35: New | L35: 2026 | M35: HONDA | N35: CR-V | O35: 40936.4 | P35: 23 | Q35: 2017 | R35: HONDA | S35: CR-V | T35: 160676 | U35: 6000 | W35: HOUSE | Y35: 7189.56 | Z35: HONDA | AA35: 7.64 | AB35: 2761.29 | AF35: =SUM(AB35:AE35) -> 2761.29 | AG35: =Y35+AF35 -> 9950.85 | AI35: 851
C36: 5 | D36: 23 | H36: C20677 | I36: SERRANO RAMOS | J36: 60632 | K36: New | L36: 2026 | M36: HONDA | N36: CR-V | O36: 38232.4 | P36: 154 | W36: HOUSE | Y36: 5392.93 | Z36: HONDA | AA36: 7.89 | AB36: 3199.14 | AC36: 2311 | AE36: 481 | AF36: =SUM(AB36:AE36) -> 5991.14 | AG36: =Y36+AF36 -> 11384.07 | AI36: 776
C37: 6 | D37: 24 | H37: C20968 | I37: SEGURA | J37: 60632 | K37: New | L37: 2026 | M37: HONDA | N37: CIVIC | O37: 30785 | P37: 10 | Q37: 2015 | R37: TOYOTA | S37: CAMRY | T37: 133865 | U37: 6000 | W37: NATE HARDING | Y37: 8111.67 | Z37: HONDA | AA37: 7.49 | AB37: 1749.94 | AD37: 1000 | AF37: =SUM(AB37:AE37) -> 2749.94 | AG37: =Y37+AF37 -> 10861.61 | AI37: 621
C38: 7 | D38: 25 | H38: DC20964A | I38: ORTEGA | J38: 60629 | K38: Used | L38: 2020 | M38: HONDA | N38: PILOT | O38: 30918.42 | P38: 4 | Q38: 2019 | R38: HONDA | S38: PASSPORT | T38: 109562 | U38: 11000 | V38: 12992 | W38: HOUSE | Y38: 2921.58 | Z38: ALLY | AA38: 10.89 | AB38: 1118.77 | AC38: 1846 | AE38: 981 | AF38: =SUM(AB38:AE38) -> 3945.77 | AG38: 3433
C39: 8 | D39: 26 | H39: C20689 | I39: ZENG | J39: 60632 | K39: New | L39: 2026 | M39: HONDA | N39: CR-V | O39: 39583.3 | P39: 150 | Q39: 2020 | R39: JEEP | S39: GR CHEROKEE | T39: 64000 | U39: 11000 | V39: 0 | W39: BRYANT ROGERS | X39: BRYAN ROGERS | Y39: 5791.53 | Z39: HONDA | AA39: 4.49 | AB39: 200 | AC39: 1363 | AF39: =SUM(AB39:AE39) -> 1563 | AG39: =Y39+AF39 -> 7354.53 | AI39: 804.5
C40: 9 | D40: 27 | H40: C20853 | I40: RUAN | J40: 60632 | K40: New | L40: 2026 | M40: HONDA | N40: CR-V | O40: 39583.3 | P40: 71 | Q40: 2022 | R40: HONDA | S40: PILOT | T40: 35540 | U40: 28000 | V40: 14550 | W40: BRYAN ROGERS | X40: BRYANT ROGERS | Y40: 7291.53 | Z40: HONDA | AA40: 4.49 | AB40: 200 | AD40: 1600 | AF40: =SUM(AB40:AE40) -> 1800 | AG40: =Y40+AF40 -> 9091.53 | AI40: 804.5
C41: 10 | D41: 28 | H41: P6256 | I41: FOSTER | J41: 60617 | K41: Used | L41: 2022 | M41: HONDA | N41: PILOT | O41: 33154 | P41: 46 | Q41: 2008 | R41: MERCEDES | S41: E300 | T41: 156629 | U41: 1 | V41: 0 | W41: BRYANT ROGERS | X41: HALEY DELUDE | Y41: 2000 | Z41: CAP 1 | AA41: 5.99 | AB41: 372 | AC41: 854 | AE41: 148 | AF41: =SUM(AB41:AE41) -> 1374 | AG41: =Y41+AF41 -> 3374
AF42: =SUM(AB42:AE42) -> 0 | AG42: =Y42+AF42 -> 0 | AH42: =SUM(AG32:AG41) -> 67284.47
...

Sheet MAIL TRACKING
F2: MON | G2: TUES | H2: WED | I2: THURS | J2: FRI | K2: SAT
D3: UPS | F3: =F15 -> 37 | G3: =G15 -> 16 | H3: =H15 -> 36 | I3: =I15 -> 50 | J3: =J15 -> 78 | K3: =K15 -> 100
A4: PIECES SENT | B4: RESPONSES | C4: TOWN | D4: ZIP | E4: ZIP TOTAL | F4: DAY 1 | G4: DAY 2 | H4: DAY 3 | I4: DAY 4 | J4: DAY 5 | K4: DAY 6
A5: 9777 | B5: =E5/A5 -> 0.0043980771 | C5: CHICAGO, IL | D5: 60608 | E5: =SUM(F5:K5) -> 43 | I5: 4 | J5: 19 | K5: 20
A6: 10462 | B6: =E6/A6 -> 0.0068820493 | C6: CHICAGO, IL | D6: 60609 | E6: =SUM(F6:K6) -> 72 | F6: 16 | G6: 8 | H6: 12 | I6: 12 | J6: 14 | K6: 10
A7: 10434 | B7: =E7/A7 -> 0.0057504313 | C7: CHICAGO, IL | D7: 60623 | E7: =SUM(F7:K7) -> 60 | H7: 5 | I7: 9 | J7: 16 | K7: 30
A8: 9773 | B8: =E8/A8 -> 0.0096183362 | C8: CHICAGO, IL | D8: 60632 | E8: =SUM(F8:K8) -> 94 | F8: 16 | G8: 7 | H8: 13 | I8: 17 | J8: 17 | K8: 24
A9: 9621 | B9: =E9/A9 -> 0.0049890864 | C9: CICERO, IL | D9: 60804 | E9: =SUM(F9:K9) -> 48 | F9: 5 | G9: 1 | H9: 6 | I9: 8 | J9: 12 | K9: 16
A12: =SUM(A5:A9) -> 50067
D14: NON FLYER
D15: TOTAL | F15: =SUM(F5:F14) -> 37 | G15: =SUM(G5:G14) -> 16 | H15: =SUM(H5:H14) -> 36 | I15: =SUM(I5:I14) -> 50 | J15: =SUM(J5:J14) -> 78 | K15: =SUM(K5:K14) -> 100 | L15: =SUM(L5:L14) -> 0 | M15: =SUM(M5:M14) -> 0 | ... O15: =SUM(O5:O14) -> 0 | P15: =SUM(P5:P8) -> 0 | Q15: =SUM(Q5:Q13) -> 0
A17: TOTAL | D17: =SUM(F15:K15) -> 317 | K17: =SUM(F15:K15) -> 317
C20: JIM | D20: 200

Sheet SLSPERSON WASHOUT
A1: F
E5: 25% COMMISSION
D7: BRYAN ROGERS
D9: Deal # | E9: Stock # | F9: Customer | G9: Customer Zip Code | H9: Source | I9: New/Used | J9: Purchase | M9: NOTES | N9: 2nd Sales Person | O9: Front Gross | P9: PACK | Q9: COMM % | R9: COMMISSION | S9: SPLIT
C11: 1 | E11: C20931A | F11: ESCALONA | I11: Used | J11: 2025 | K11: HONDA | L11: HR-V | M11: SPLIT NICK WILEY | O11: 5113.2 | P11: 0 | Q11: 0.125 | R11: =O11*Q11 -> 639.15 | S11: 0
C12: 2 | E12: C20699 | F12: PULIDO | I12: New | J12: 2025 | K12: HONDA | L12: PILOT | O12: 9464.81 | P12: 0 | Q12: 0.25 | R12: =O12*Q12 -> 2366.2025 | S12: 0
C13: 3 | E13: C20237A | F13: MONDRAGON | I13: Used | J13: 2023 | K13: SUBARU | L13: OUTBACK | O13: 3758.31 | P13: 0 | Q13: 0.25 | R13: =O13*Q13 -> 939.5775 | S13: 0
P14: 0 | Q14: 0.25 | R14: =O14*Q14 -> 0 | S14: =R14/2 -> 0
P15: 0 | Q15: 0.25 | R15: =SUM(O15-P15)*0.25 -> 0 | S15: 0
Q16: 0.25 | R16: =SUM(O16-P16)*0.25 -> 0 | S16: 0
Q17: 0.25 | R17: =SUM(O17-P17)*0.25 -> 0 | S17: 0
Q18: 0.25 | R18: =SUM(O18-P18)*0.25 -> 0 | S18: =(O18*0.25)/2 -> 0
Q19: 0.25 | R19: =SUM(O19-P19)*0.25 -> 0 | S19: =(O19*0.25)/2 -> 0
Q20: 0.25 | R20: =SUM(O20-P20)*0.25 -> 0 | S20: =(O20*0.25)/2 -> 0
Q21: 0.25 | R21: =SUM(O21-P21)*0.25 -> 0 | S21: =(O21*0.25)/2 -> 0
Q22: 0.25 | R22: =SUM(O22-P22)*0.25 -> 0 | S22: =(O22*0.25)/2 -> 0
Q23: 0.25 | R23: =SUM(O23-P23)*0.25 -> 0 | S23: =(O23*0.25)/2 -> 0
Q24: 0.25 | R24: =SUM(O24-P24)*0.25 -> 0 | S24: =(O24*0.25)/2 -> 0
Q25: 0.25 | R25: =SUM(O25-P25)*0.25 -> 0 | S25: =(O25*0.25)/2 -> 0
Q26: 0.25 | R26: =SUM(O26-P26)*0.25 -> 0 | S26: =(O26*0.25)/2 -> 0
Q27: 0.25 | R27: =(O27*0.25)/2 -> 0 | S27: =(O27*0.25)/2 -> 0
C28: 4 | E28: C20654A | F28: MONDRAGON | I28: Used | J28: 2022 | K28: CHEVY | L28: 1500 | O28: 6061.7 | Q28: 0.25 | R28: =O28*Q28 -> 1515.425 | S28: 0
C29: 5 | E29: C20689 | F29: ZENG | I29: New | J29: 2026 | K29: HONDA | L29: CR-V | M29: SPLIT BRYANT ROGERS | O29: 5791.53 | P29: 0 | Q29: 0.125 | R29: =O29*Q29 -> 723.94125 | S29: 0
C30: 6 | E30: C20853 | F30: RUAN | I30: New | J30: 2026 | K30: HONDA | L30: CR-V | M30: SPLIT BRYANT ROGERS | O30: 7291.53 | P30: 0 | Q30: 0.125 | R30: =O30*Q30 -> 911.44125 | S30: 0
C31: 7 | E31: XP6231 | F31: BEAMON | I31: Used | J31: 2024 | K31: TOYOTA | L31: RAV 4 | M31: SPLIT HALEY DELUDE | O31: 2000 | P31: 0 | Q31: 0.125 | R31: =O31*Q31 -> 250 | S31: 0
E32: C20673 | F32: DITTMANN | I32: New | J32: 2026 | K32: HONDA | L32: HR-V | M32: SPLIT BRYAN ROGERS | O32: 6124.05 | P32: 0 | Q32: 0.125 | R32: =(O32*0.25)/2 -> 765.50625 | S32: =(O32*0.25)/2 -> 765.50625
Q33: 0.25 | R33: =(O33*0.25)/2 -> 0 | S33: =(O33*0.25)/2 -> 0
Q34: 0.25 | R34: 0 | S34: 0
Q35: 0.25 | R35: =(O35*0.25)/2 -> 0 | S35: =(O35*0.25)/2 -> 0
O36: =SUM(O11:O35) -> 45605.13 | R36: =SUM(R11:R34) -> 8111.2437
C37: =SUM(C11:C35) -> 28 | N37: PVR
D41: NICK WILEY
D43: Deal # | E43: Stock # | F43: Customer | G43: Customer Zip Code | H43: Source | I43: New/Used | J43: Purchase | M43: NOTES | N43: 2nd Sales Person | O43: Front Gross | P43: PACK | Q43: COMM % | R43: COMMISSION | S43: SPLIT
J44: Year | K44: Make | L44: Model
C45: 1 | E45: C20931A | F45: ESCALONA | I45: Used | J45: 2025 | K45: HONDA | L45: HR-V | M45: SPLIT BRYAN ROGERS | O45: 5113.2 | P45: 0 | Q45: 0.125 | R45: =O45*Q45 -> 639.15 | S45: 0
C46: 2 | E46: C20976 | F46: DELATORRE | I46: New | J46: 2026 | K46: HONDA | L46: CR-V | M46: SPLIT JOSE TORRES | O46: 4589.8 | P46: 0 | Q46: 0.125 | R46: =O46*Q46 -> 573.725 | S46: 0
C47: 3 | E47: C20540A | F47: DEER/PHILLIPS | I47: Used | J47: 2022 | K47: HONDA | L47: HR-V | M47: SPLIT JOSE TORRES | O47: 2157 | P47: 0 | Q47: 0.125 | R47: =O47*Q47 -> 269.625 | S47: 0
C48: 4 | E48: C20886A | F48: ARCE | I48: Used | J48: 2020 | K48: HONDA | L48: CIVIC | O48: 2000 | P48: 0 | Q48: 0.25 | R48: =O48*Q48 -> 500
P49: 0 | Q49: 0.25 | R49: =O49*Q49 -> 0 | S49: 0
Q50: 0.25 | R50: =O50*Q50 -> 0 | S50: =R50 -> 0
...

Sheet RECAP
J2: SALES PEOPLE SUMMARY
B3: CHICAGO NORTHSIDE TOYOTA | J3: ='SLSPERSON WASHOUT'!D7 -> BRYAN ROGERS | P3: ='SLSPERSON WASHOUT'!R36 -> 8111.2437
B4: 46054 | J4: ='SLSPERSON WASHOUT'!D41 -> NICK WILEY | P4: ='SLSPERSON WASHOUT'!R71 -> 1982.5
J5: ='SLSPERSON WASHOUT'!D76 -> CHRIS MARTIN | P5: ='SLSPERSON WASHOUT'!R112 -> 2165.6912
C6: TOTAL COMMISSIONABLE GROSS | G6: ='DEAL LOG'!AH57 -> 281580.79 | J6: ='SLSPERSON WASHOUT'!D118 -> JOSE TORRES | P6: ='SLSPERSON WASHOUT'!R148 -> 3596.2913
J7: ='SLSPERSON WASHOUT'!D154 -> MAYCON MIKE GUIMARAES | P7: ='SLSPERSON WASHOUT'!R184 -> 250
C8: JDE COMMISSION 35% | F8: - | G8: =G6*0.35 -> 98553.277 | J8: ='SLSPERSON WASHOUT'!D190 -> MIKE LASHLEY | P8: ='SLSPERSON WASHOUT'!R222 -> 500
J9: ='SLSPERSON WASHOUT'!D226 -> OSSIE SAMPSON | P9: ='SLSPERSON WASHOUT'!R258 -> 557.44125
C10: MARKETING COST | F10: - | G10: 0 | J10: ='SLSPERSON WASHOUT'!D262 -> ABDUL AL TABBAH | P10: ='SLSPERSON WASHOUT'!R292 -> 500
J11: ='SLSPERSON WASHOUT'!D297 -> BRYANT ROGERS | P11: ='SLSPERSON WASHOUT'!R327 -> 2900.8888
C12: NON COMM GROSS- | F12: + | G12: 24664 | J12: ='SLSPERSON WASHOUT'!D335 -> NATE HARDING | P12: ='SLSPERSON WASHOUT'!R353 -> 2027.9175
C13: 600 USED 376 DOC | J13: ='SLSPERSON WASHOUT'!F335 -> IRELAND BARE | P13: ='SLSPERSON WASHOUT'!R353 -> 2027.9175
C14: TOTAL SALE GROSS | G14: =G6+G12 -> 306244.79 | J14: ='SLSPERSON WASHOUT'!D359 -> HALEY DELUDE | P14: ='SLSPERSON WASHOUT'!R389 -> 500
C16: REPS COMMISSIONS | F16: - | G16: =P28 -> 25119.891
C18: VARIABLE NET | F18: - | G18: =G14-G8 -> 207691.51
C20: TOTAL NET | G20: =G14-G8-G16-G22 -> 182571.62
C22: MIS EXPENSES | G22: 0
C23: HELIUM/PRIZE GIVEAWAYS ETC
C25: JDE COMMISSION | G25: =G8 -> 98553.277
C27: 23 NEW 16 USED
J28: TOTAL REPS | P28: =SUM(P3:Q19) -> 25119.891

Sheet REG $ FORM
D1: GIFT REGISTRATION FORM
B3: DATE:
B5: SLS PERSON | C5: FIRST / LAST NAME | D5: CITY | E5: STATE | F5: $$ GIVEN

Sheet PLATE LOG
E2: LIST PLATES BELOW
B3: 395 K | C3: 395 U | D3: 395 O | E3: 395 J | F3: 395 V | G3: 395 T | H3: 395 E
B5: SLS PERSON | C5: CUSTOMER | D5: VEHICLE | E5: PLATE NUMBER | F5: TIME OUT | G5: TIME IN | H5: COMMENTS

Sheet Washout
A1: Salesman: | B1: CHARLIE WINTERS | M1: DANETTE
A2: DEAL# | B2: CUSTOMER | C2: YEAR | D2: MAKE | E2: MODEL | F2: SOURCE | G2: SPLIT | H2: F GROSS | I2: % COMM | J2: PACK | K2: COMM $
K3: =H3*0.25 -> 0 | L3: Full Deals
K4: 500
A5: {=IFERROR(SMALL(IF('Sale Rollup'!$L$2:$L$240=$B$1,ROW('Sale Rollup'!$L$2:$L$240)),ROW(3:3))," ")}
A6: {=IFERROR(SMALL(IF('Sale Rollup'!$L$2:$L$240=$B$1,ROW('Sale Rollup'!$L$2:$L$240)),ROW(4:4))," ")}
A11: {=IFERROR(SMALL(IF('Sale Rollup'!$L$2:$L$240=$B$1,ROW('Sale Rollup'!$L$2:$L$240)),ROW(9:9))," ")}
A12: {=IFERROR(SMALL(IF('Sale Rollup'!$L$2:$L$240=$B$1,ROW('Sale Rollup'!$L$2:$L$240)),ROW(10:10))," ")}
A13: {=IFERROR(SMALL(IF('Sale Rollup'!$L$2:$L$240=$B$1,ROW('Sale Rollup'!$L$2:$L$240)),ROW(11:11))," ")}
A14: {=IFERROR(SMALL(IF('Sale Rollup'!$L$2:$L$240=$B$1,ROW('Sale Rollup'!$L$2:$L$240)),ROW(12:12))," ")}
A15: {=IFERROR(SMALL(IF('Sale Rollup'!$L$2:$L$240=$B$1,ROW('Sale Rollup'!$L$2:$L$240)),ROW(13:13))," ")}
A16: {=IFERROR(SMALL(IF('Sale Rollup'!$L$2:$L$240=$B$1,ROW('Sale Rollup'!$L$2:$L$240)),ROW(14:14))," ")}
A17: {=IFERROR(SMALL(IF('Sale Rollup'!$L$2:$L$240=$B$1,ROW('Sale Rollup'!$L$2:$L$240)),ROW(15:15))," ")}
A18: {=IFERROR(SMALL(IF('Sale Rollup'!$L$2:$L$240=$B$1,ROW('Sale Rollup'!$L$2:$L$240)),ROW(16:16))," ")}
A19: {=IFERROR(SMALL(IF('Sale Rollup'!$L$2:$L$240=$B$1,ROW('Sale Rollup'!$L$2:$L$240)),ROW(17:17))," ")}
A20: {=IFERROR(SMALL(IF('Sale Rollup'!$L$2:$L$240=$B$1,ROW('Sale Rollup'!$L$2:$L$240)),ROW(18:18))," ")}
A21: {=IFERROR(SMALL(IF('Sale Rollup'!$L$2:$L$240=$B$1,ROW('Sale Rollup'!$L$2:$L$240)),ROW(19:19))," ")}
A22: {=IFERROR(SMALL(IF('Sale Rollup'!$L$2:$L$240=$B$1,ROW('Sale Rollup'!$L$2:$L$240)),ROW(20:20))," ")}
A23: {=IFERROR(SMALL(IF('Sale Rollup'!$O$2:$O$240=$B$1,ROW('Sale Rollup'!$L$2:$L$240)),ROW(1:1))," ")} | L23: Split Deals
A24: {=IFERROR(SMALL(IF('Sale Rollup'!$O$2:$O$240=$B$1,ROW('Sale Rollup'!$L$2:$L$240)),ROW(2:2))," ")}
A25: {=IFERROR(SMALL(IF('Sale Rollup'!$O$2:$O$240=$B$1,ROW('Sale Rollup'!$L$2:$L$240)),ROW(3:3))," ")}
A26: {=IFERROR(SMALL(IF('Sale Rollup'!$O$2:$O$240=$B$1,ROW('Sale Rollup'!$L$2:$L$240)),ROW(4:4))," ")}
A27: {=IFERROR(SMALL(IF('Sale Rollup'!$O$2:$O$240=$B$1,ROW('Sale Rollup'!$L$2:$L$240)),ROW(5:5))," ")}
A28: {=IFERROR(SMALL(IF('Sale Rollup'!$O$2:$O$240=$B$1,ROW('Sale Rollup'!$L$2:$L$240)),ROW(6:6))," ")}
A29: {=IFERROR(SMALL(IF('Sale Rollup'!$O$2:$O$240=$B$1,ROW('Sale Rollup'!$L$2:$L$240)),ROW(7:7))," ")}
A30: {=IFERROR(SMALL(IF('Sale Rollup'!$O$2:$O$240=$B$1,ROW('Sale Rollup'!$L$2:$L$240)),ROW(8:8))," ")}
A31: {=IFERROR(SMALL(IF('Sale Rollup'!$O$2:$O$240=$B$1,ROW('Sale Rollup'!$L$2:$L$240)),ROW(9:9))," ")}
A32: {=IFERROR(SMALL(IF('Sale Rollup'!$O$2:$O$240=$B$1,ROW('Sale Rollup'!$L$2:$L$240)),ROW(10:10))," ")}
A33: Deals
A34: =IF('Roster & Tables'!J29=0,"","Pack") | B34: Full | C34: 0 | E34: Split | F34: 8 | K34: =IF('Roster & Tables'!J29=0,"",((C34*'Roster & Tables'!J29)+(F34*('Roster & Tables'!J29/2))))
A35: Total Commission | K35: =SUM(K3:K7) -> 500 | M35: 1572.08
A37: Salesman: | B37: GARY/MIKE
A38: DEAL # | B38: CUSTOMER | C38: YEAR | D38: MAKE | E38: MODEL | F38: SOURCE | G38: SPLIT | H38: F GROSS | I38: % COMM | J38: PACK | K38: COMM $
K39: =H39*0.25 -> 0 | L39: Full Deals
K40: =H40*0.25 -> 0
K41: =(H41*0.65)*0.25 -> 0 | M41: =(H41*0.35)*0.25 -> 0 | N41: DANETTE
K42: =H42*0.25 -> 0
K43: =H43*0.25 -> 0
K44: =H44*0.25 -> 0
K45: =(H45*0.65)*0.25 -> 0 | M45: =(H45*0.35)*0.25 -> 0 | N45: DANETTE
...

Sheet Pay Calc.
A1: Customer Last | D1: Customer Last | G1: Customer Last | J1: Customer Last | M1: Customer Last | P1: Customer Last | S1: Customer Last
A2: Stock# | D2: Stock# | G2: Stock# | J2: Stock# | M2: Stock# | P2: Stock# | S2: Stock#
A3: Vehicle Sales Price | B3: 32915 | D3: Vehicle Sales Price | E3: 0 | G3: Vehicle Sales Price | H3: 0 | J3: Vehicle Sales Price | K3: 0 | M3: Vehicle Sales Price | N3: 0 | P3: Vehicle Sales Price | Q3: 0 | S3: Vehicle Sales Price | T3: 0
A4: State Sales Tax Rate | B4: 0.06 | D4: State Sales Tax Rate | E4: 0 | G4: State Sales Tax Rate | H4: 0 | J4: State Sales Tax Rate | K4: 0 | M4: State Sales Tax Rate | N4: 0 | P4: State Sales Tax Rate | Q4: 0 | S4: State Sales Tax Rate | T4: 0
A5: State Sales Tax | B5: =SUM(B3-B17)*B4 -> 924.9 | D5: State Sales Tax | E5: =E3*E4 -> 0 | G5: State Sales Tax | H5: =H3*H4 -> 0 | J5: State Sales Tax | K5: =K3*K4 -> 0 | M5: State Sales Tax | N5: =N3*N4 -> 0 | P5: State Sales Tax | Q5: =Q3*Q4 -> 0 | S5: State Sales Tax | T5: =T3*T4 -> 0
A6: IRS Luxury Tax | B6: =IF(B3>55000,(B3-55000)*0.05,0) -> 0 | D6: IRS Luxury Tax | E6: =IF(E3>55000,(E3-55000)*0.05,0) -> 0 | G6: IRS Luxury Tax | H6: =IF(H3>55000,(H3-55000)*0.05,0) -> 0 | J6: IRS Luxury Tax | K6: =IF(K3>55000,(K3-55000)*0.05,0) -> 0 | M6: IRS Luxury Tax | N6: =IF(N3>55000,(N3-55000)*0.05,0) -> 0 | P6: IRS Luxury Tax | Q6: =IF(Q3>55000,(Q3-55000)*0.05,0) -> 0 | S6: IRS Luxury Tax | T6: =IF(T3>55000,(T3-55000)*0.05,0) -> 0
A7: State Inspection Fee | B7: 0 | D7: State Inspection Fee | E7: 0 | G7: State Inspection Fee | H7: 0 | J7: State Inspection Fee | K7: 0 | M7: State Inspection Fee | N7: 0 | P7: State Inspection Fee | Q7: 0 | S7: State Inspection Fee | T7: 0
A8: Documentary Fee | B8: 399 | D8: Documentary Fee | E8: 0 | G8: Documentary Fee | H8: 0 | J8: Documentary Fee | K8: 0 | M8: Documentary Fee | N8: 0 | P8: Documentary Fee | Q8: 0 | S8: Documentary Fee | T8: 0
A9: License Fee | B9: 34 | D9: License Fee | E9: 0 | G9: License Fee | H9: 0 | J9: License Fee | K9: 0 | M9: License Fee | N9: 0 | P9: License Fee | Q9: 0 | S9: License Fee | T9: 0
A10: Warranty | B10: 0 | D10: Warranty | E10: 0 | G10: Warranty | H10: 0 | J10: Warranty | K10: 0 | M10: Warranty | N10: 0 | P10: Warranty | Q10: 0 | S10: Warranty | T10: 0
A11: Gap Insurance | B11: 0 | D11: Gap Insurance | E11: 0 | G11: Gap Insurance | H11: 0 | J11: Gap Insurance | K11: 0 | M11: Gap Insurance | N11: 0 | P11: Gap Insurance | Q11: 0 | S11: Gap Insurance | T11: 0
A12: After Market | B12: 0 | D12: After Market | E12: 0 | G12: After Market | H12: 0 | J12: After Market | K12: 0 | M12: After Market | N12: 0 | P12: After Market | Q12: 0 | S12: After Market | T12: 0
A13: SUB TOTAL | B13: =SUM(B3:B12) -> 34272.96 | D13: SUB TOTAL | E13: =SUM(E3,E5,E6,E7,E8,E9,E9,E10,E11,E12) -> 0 | G13: SUB TOTAL | H13: =SUM(H3,H5,H6,H7,H8,H9,H9,H10,H11,H12) -> 0 | J13: SUB TOTAL | K13: =SUM(K3,K5,K6,K7,K8,K9,K9,K10,K11,K12) -> 0 | M13: SUB TOTAL | N13: =SUM(N3,N5,N6,N7,N8,N9,N9,N10,N11,N12) -> 0 | P13: SUB TOTAL | Q13: =SUM(Q3,Q5,Q6,Q7,Q8,Q9,Q9,Q10,Q11,Q12) -> 0 | S13: SUB TOTAL | T13: =SUM(T3,T5,T6,T7,T8,T9,T9,T10,T11,T12) -> 0
A15: Down Payment | B15: 0 | D15: Down Payment | E15: 0 | G15: Down Payment | H15: 0 | J15: Down Payment | K15: 0 | M15: Down Payment | N15: 0 | P15: Down Payment | Q15: 0 | S15: Down Payment | T15: 0
A16: Manufacturer Rebate | B16: 0 | D16: Manufacturer Rebate | E16: 0 | G16: Manufacturer Rebate | H16: 0 | J16: Manufacturer Rebate | K16: 0 | M16: Manufacturer Rebate | N16: 0 | P16: Manufacturer Rebate | Q16: 0 | S16: Manufacturer Rebate | T16: 0
A17: Trade-in Allowance | B17: 17500 | D17: Trade-in Allowance | E17: 0 | G17: Trade-in Allowance | H17: 0 | J17: Trade-in Allowance | K17: 0 | M17: Trade-in Allowance | N17: 0 | P17: Trade-in Allowance | Q17: 0 | S17: Trade-in Allowance | T17: 0
A18: Owed on Trade | B18: 21750 | D18: Owed on Trade | E18: 0 | G18: Owed on Trade | H18: 0 | J18: Owed on Trade | K18: 0 | M18: Owed on Trade | N18: 0 | P18: Owed on Trade | Q18: 0 | S18: Owed on Trade | T18: 0
A19: Trade Equity | B19: =B17-B18 -> -4250 | D19: Trade Equity | E19: =E17-E18 -> 0 | G19: Trade Equity | H19: =H17-H18 -> 0 | J19: Trade Equity | K19: =K17-K18 -> 0 | M19: Trade Equity | N19: =N17-N18 -> 0 | P19: Trade Equity | Q19: =Q17-Q18 -> 0 | S19: Trade Equity | T19: =T17-T18 -> 0
A20: Total Equity | B20: =B15+B16+B19 -> -4250 | D20: Total Equity | E20: =E15+E16+E19 -> 0 | G20: Total Equity | H20: =H15+H16+H19 -> 0 | J20: Total Equity | K20: =K15+K16+K19 -> 0 | M20: Total Equity | N20: =N15+N16+N19 -> 0 | P20: Total Equity | Q20: =Q15+Q16+Q19 -> 0 | S20: Total Equity | T20: =T15+T16+T19 -> 0
A22: Total Cost | B22: =B13 -> 34272.96 | D22: Total Cost | E22: =E13 -> 0 | G22: Total Cost | H22: =H13 -> 0 | J22: Total Cost | K22: =K13 -> 0 | M22: Total Cost | N22: =N13 -> 0 | P22: Total Cost | Q22: =Q13 -> 0 | S22: Total Cost | T22: =T13 -> 0
A23: Total Equity | B23: =B20 -> -4250 | D23: Total Equity | E23: =E20 -> 0 | G23: Total Equity | H23: =H20 -> 0 | J23: Total Equity | K23: =K20 -> 0 | M23: Total Equity | N23: =N20 -> 0 | P23: Total Equity | Q23: =Q20 -> 0 | S23: Total Equity | T23: =T20 -> 0
A24: Total Amount Financed | B24: =B22-B33 -> 34272.96 | D24: Total Amount Financed | G24: Total Amount Financed | H24: =H22-H23 -> 0 | J24: Total Amount Financed | K24: =K22-K23 -> 0 | M24: Total Amount Financed | N24: =N22-N23 -> 0 | P24: Total Amount Financed | Q24: =Q22-Q23 -> 0 | S24: Total Amount Financed | T24: =T22-T23 -> 0
A26: Annual % Rate (APR) | B26: 0.0599 | D26: Annual % Rate (APR) | G26: Annual % Rate (APR) | J26: Annual % Rate (APR) | M26: Annual % Rate (APR) | P26: Annual % Rate (APR) | S26: Annual % Rate (APR)
A27: # of Monthly Payments | B27: 75 | D27: # of Monthly Payments | G27: # of Monthly Payments | J27: # of Monthly Payments | M27: # of Monthly Payments | P27: # of Monthly Payments | S27: # of Monthly Payments
A28: Monthly Payment | B28: =-PMT(B26/12,B27,B24) -> 548.96368 | D28: Monthly Payment | G28: Monthly Payment | H28: =-PMT(H26/12,H27,H24) -> #NUM! | J28: Monthly Payment | K28: =-PMT(K26/12,K27,K24) -> #NUM! | M28: Monthly Payment | N28: =-PMT(N26/12,N27,N24) -> #NUM! | P28: Monthly Payment | Q28: =-PMT(Q26/12,Q27,Q24) -> #NUM! | S28: Monthly Payment | T28: =-PMT(T26/12,T27,T24) -> #NUM!
A30: Bank: | D30: Bank: | G30: Bank: | J30: Bank: | M30: Bank: | P30: Bank: | S30: Bank:
A31: COST | B31: 29500 | D31: Cost | E31: 0 | G31: Cost | H31: 0 | J31: Cost | K31: 0 | M31: Cost | N31: 0 | P31: Cost | Q31: 0 | S31: Cost | T31: 0
A32: Pack | B32: 0 | D32: Pack | E32: 0 | G32: Pack | H32: 0 | J32: Pack | K32: 0 | M32: Pack | N32: 0 | P32: Pack | Q32: 0 | S32: Pack | T32: 0
A33: ACV | B33: 0 | D33: ACV | E33: 0 | G33: ACV | H33: 0 | J33: ACV | K33: 0 | M33: ACV | N33: 0 | P33: ACV | Q33: 0 | S33: ACV | T33: 0
A34: Bank Fee % | B34: 0 | D34: Bank Fee % | E34: 0 | G34: Bank Fee % | H34: 0 | J34: Bank Fee % | K34: 0 | M34: Bank Fee % | N34: 0 | P34: Bank Fee % | Q34: 0 | S34: Bank Fee % | T34: 0
A35: Bank Fee | B35: =B34*B24 -> 0 | D35: Bank Fee | E35: =E34*E24 -> 0 | G35: Bank Fee | H35: =H34*H24 -> 0 | J35: Bank Fee | K35: =K34*K24 -> 0 | M35: Bank Fee | N35: =N34*N24 -> 0 | P35: Bank Fee | Q35: =Q34*Q24 -> 0 | S35: Bank Fee | T35: =T34*T24 -> 0
A36: Acq. Fee | B36: 0 | D36: Acq. Fee | E36: 0 | G36: Acq. Fee | H36: 0 | J36: Acq. Fee | K36: 0 | M36: Acq. Fee | N36: 0 | P36: Acq. Fee | Q36: 0 | S36: Acq. Fee | T36: 0
A37: Warranty Cost | B37: 0 | D37: Warranty Cost | E37: 0 | G37: Warranty Cost | H37: 0 | J37: Warranty Cost | K37: 0 | M37: Warranty Cost | N37: 0 | P37: Warranty Cost | Q37: 0 | S37: Warranty Cost | T37: 0
A38: Gap Cost | B38: 0 | D38: Gap Cost | E38: 0 | G38: Gap Cost | H38: 0 | J38: Gap Cost | K38: 0 | M38: Gap Cost | N38: 0 | P38: Gap Cost | Q38: 0 | S38: Gap Cost | T38: 0
A39: Buy Rate | B39: 0 | D39: Buy Rate | E39: 0 | G39: Buy Rate | H39: 0 | J39: Buy Rate | K39: 0 | M39: Buy Rate | N39: 0 | P39: Buy Rate | Q39: 0 | S39: Buy Rate | T39: 0
A40: Book Value | B40: 29500 | D40: Book Value | E40: 0 | G40: Book Value | H40: 0 | J40: Book Value | K40: 0 | M40: Book Value | N40: 0 | P40: Book Value | Q40: 0 | S40: Book Value | T40: 0
A42: Line 3 | B42: =B24/B40 -> 1.1617953 | D42: Line 3 | E42: =(E3-E20)/E31 -> #DIV/0! | G42: Line 3 | H42: =(H3-H20)/H31 -> #DIV/0! | J42: Line 3 | K42: =(K3-K20)/K31 -> #DIV/0! | M42: Line 3 | N42: =(N3-N20)/N31 -> #DIV/0! | P42: Line 3 | Q42: =(Q3-Q20)/Q31 -> #DIV/0! | S42: Line 3 | T42: =(T3-T20)/T31 -> #DIV/0!
A43: Line 5 | B43: =B24/B40 -> 1.1617953 | D43: Line 5 | E43: =E24/E40 -> #DIV/0! | G43: Line 5 | H43: =H24/H40 -> #DIV/0! | J43: Line 5 | K43: =K24/K40 -> #DIV/0! | M43: Line 5 | N43: =N24/N40 -> #DIV/0! | P43: Line 5 | Q43: =Q24/Q40 -> #DIV/0! | S43: Line 5 | T43: =T24/T40 -> #DIV/0!
A45: PRODUCT | B45: =SUM(B10-B37)+(B11-B38) -> 0 | D45: PRODUCT | E45: =SUM(E10-E37)+(E11-E38) -> 0 | G45: PRODUCT | H45: =SUM(H10-H37)+(H11-H38) -> 0 | J45: PRODUCT | K45: =SUM(K10-K37)+(K11-K38) -> 0 | M45: PRODUCT | N45: =SUM(N10-N37)+(N11-N38) -> 0 | P45: PRODUCT | Q45: =SUM(Q10-Q37)+(Q11-Q38) -> 0 | S45: PRODUCT | T45: =SUM(T10-T37)+(T11-T38) -> 0
A46: RESERVE | B46: =-((B27*B28)-((PMT(B39/12,B27,B24)*-1)*B27))*(-0.75) -> 5174.4871 | D46: RESERVE | E46: =-((E27*E28)-((PMT(E39/12,E27,E24)*-1)*E27))*(-0.75) -> #NUM! | G46: RESERVE | H46: =-((H27*H28)-((PMT(H39/12,H27,H24)*-1)*H27))*(-0.75) -> #NUM! | J46: RESERVE | K46: =-((K27*K28)-((PMT(K39/12,K27,K24)*-1)*K27))*(-0.75) -> #NUM! | M46: RESERVE | N46: =-((N27*N28)-((PMT(N39/12,N27,N24)*-1)*N27))*(-0.75) -> #NUM! | P46: RESERVE | Q46: =-((Q27*Q28)-((PMT(Q39/12,Q27,Q24)*-1)*Q27))*(-0.75) -> #NUM! | S46: RESERVE | T46: =-((T27*T28)-((PMT(T39/12,T27,T24)*-1)*T27))*(-0.75) -> #NUM!
...

Sheet Sale Rollup
B1: Deal # | C1: Customer Last Name | D1: Source | E1: New, Used, Trade | F1: Year | G1: Make | H1: Model | I1: Front Gross | J1: Total Commission | K1: Split | L1: Salesperson | M1: Percent A | N1: Commission Saleperson 1 | O1: 2nd Salesperson | P1: Percent B | Q1: Commission Saleperson 2
A2: 1 | B2: =IF('DEAL LOG'!H9=ISBLANK(TRUE),"",'DEAL LOG'!H9) | C2: =IF('DEAL LOG'!$I$9=ISBLANK(TRUE),"",'DEAL LOG'!I9) | D2: =IF(#REF!=ISBLANK(TRUE),"",#REF!) -> #REF! | E2: =IF('DEAL LOG'!K9=ISBLANK(TRUE),"",'DEAL LOG'!K9) | F2: =IF('DEAL LOG'!L9=ISBLANK(TRUE),"",'DEAL LOG'!L9) | G2: =IF('DEAL LOG'!M9=ISBLANK(TRUE),"",'DEAL LOG'!M9) | H2: =IF('DEAL LOG'!N9=ISBLANK(TRUE),"",'DEAL LOG'!N9) | I2: =IF('DEAL LOG'!Y9=ISBLANK(TRUE),"",'DEAL LOG'!Y9) | J2: =I2*0.25 -> 0 | K2: =IF(M2<1,"Yes","No") -> No | L2: =IF('DEAL LOG'!W9=ISBLANK(TRUE),"",'DEAL LOG'!W9) | M2: 1 | N2: =J2*M2 -> 0 | O2: =IF('DEAL LOG'!X9=ISBLANK(TRUE),"",'DEAL LOG'!X9) | P2: =IF(#REF!=ISBLANK(TRUE),"",#REF!) -> #REF! | Q2: =J2*P2 -> #REF!
A3: 1 | B3: =IF('DEAL LOG'!H10=ISBLANK(TRUE),"",'DEAL LOG'!H10) -> C20931A | C3: =IF('DEAL LOG'!$I$9=ISBLANK(TRUE),"",'DEAL LOG'!I10) | D3: =IF(#REF!=ISBLANK(TRUE),"",#REF!) -> #REF! | E3: =IF('DEAL LOG'!K10=ISBLANK(TRUE),"",'DEAL LOG'!K10) -> Used | F3: =IF('DEAL LOG'!L10=ISBLANK(TRUE),"",'DEAL LOG'!L10) -> 2025 | G3: =IF('DEAL LOG'!M10=ISBLANK(TRUE),"",'DEAL LOG'!M10) -> HONDA | H3: =IF('DEAL LOG'!N10=ISBLANK(TRUE),"",'DEAL LOG'!N10) -> HR-V | I3: =IF('DEAL LOG'!Y10=ISBLANK(TRUE),"",'DEAL LOG'!Y10) -> 5113.2 | J3: =I3*0.25 -> 1278.3 | K3: =IF(M3<1,"Yes","No") -> Yes | L3: =IF('DEAL LOG'!W10=ISBLANK(TRUE),"",'DEAL LOG'!W10) -> BRYAN ROGERS | M3: 0.5 | N3: =J3*M3 -> 639.15 | O3: =IF('DEAL LOG'!X10=ISBLANK(TRUE),"",'DEAL LOG'!X10) -> NICK WILEY | P3: 0.5 | Q3: =J3*P3 -> 639.15
A4: 1 | B4: =IF('DEAL LOG'!H13=ISBLANK(TRUE),"",'DEAL LOG'!H13) | C4: =IF('DEAL LOG'!$I$9=ISBLANK(TRUE),"",'DEAL LOG'!I13) | D4: =IF(#REF!=ISBLANK(TRUE),"",#REF!) -> #REF! | E4: =IF('DEAL LOG'!K13=ISBLANK(TRUE),"",'DEAL LOG'!K13) | F4: =IF('DEAL LOG'!L13=ISBLANK(TRUE),"",'DEAL LOG'!L13) | G4: =IF('DEAL LOG'!M13=ISBLANK(TRUE),"",'DEAL LOG'!M13) | H4: =IF('DEAL LOG'!N13=ISBLANK(TRUE),"",'DEAL LOG'!N13) | I4: =IF('DEAL LOG'!Y13=ISBLANK(TRUE),"",'DEAL LOG'!Y13) | J4: =I4*0.25 -> 0 | K4: =IF(M4<1,"Yes","No") -> Yes | L4: =IF('DEAL LOG'!W13=ISBLANK(TRUE),"",'DEAL LOG'!W13) | M4: 0.5 | N4: =J4*M4 -> 0 | O4: =IF('DEAL LOG'!X13=ISBLANK(TRUE),"",'DEAL LOG'!X13) | P4: 0.5 | Q4: =J4*P4 -> 0
A5: 1 | B5: =IF(#REF!=ISBLANK(TRUE),"",#REF!) -> #REF! | C5: =IF('DEAL LOG'!$I$9=ISBLANK(TRUE),"",#REF!) | D5: =IF(#REF!=ISBLANK(TRUE),"",#REF!) -> #REF! | E5: =IF(#REF!=ISBLANK(TRUE),"",#REF!) -> #REF! | F5: =IF(#REF!=ISBLANK(TRUE),"",#REF!) -> #REF! | G5: =IF(#REF!=ISBLANK(TRUE),"",#REF!) -> #REF! | H5: =IF(#REF!=ISBLANK(TRUE),"",#REF!) -> #REF! | I5: =IF(#REF!=ISBLANK(TRUE),"",#REF!) -> #REF! | J5: =I5*0.25 -> #REF! | K5: =IF(M5<1,"Yes","No") -> No | L5: =IF(#REF!=ISBLANK(TRUE),"",#REF!) -> #REF! | M5: 1 | N5: =J5*M5 -> #REF! | O5: =IF(#REF!=ISBLANK(TRUE),"",#REF!) -> #REF! | P5: =IF(#REF!=ISBLANK(TRUE),"",#REF!) -> #REF! | Q5: =J5*P5 -> #REF!
A6: 1 | B6: =IF(#REF!=ISBLANK(TRUE),"",#REF!) -> #REF! | C6: =IF('DEAL LOG'!$I$9=ISBLANK(TRUE),"",#REF!) | D6: =IF(#REF!=ISBLANK(TRUE),"",#REF!) -> #REF! | E6: =IF(#REF!=ISBLANK(TRUE),"",#REF!) -> #REF! | F6: =IF(#REF!=ISBLANK(TRUE),"",#REF!) -> #REF! | G6: =IF(#REF!=ISBLANK(TRUE),"",#REF!) -> #REF! | H6: =IF(#REF!=ISBLANK(TRUE),"",#REF!) -> #REF! | I6: =IF(#REF!=ISBLANK(TRUE),"",#REF!) -> #REF! | J6: =I6*0.25 -> #REF! | K6: =IF(M6<1,"Yes","No") -> No | L6: =IF(#REF!=ISBLANK(TRUE),"",#REF!) -> #REF! | M6: 1 | N6: =J6*M6 -> #REF! | O6: =IF(#REF!=ISBLANK(TRUE),"",#REF!) -> #REF! | P6: =IF(#REF!=ISBLANK(TRUE),"",#REF!) -> #REF! | Q6: =J6*P6 -> #REF!
A7: 1 | B7: =IF('DEAL LOG'!H16=ISBLANK(TRUE),"",'DEAL LOG'!H16) -> DC20851 | C7: =IF('DEAL LOG'!$I$9=ISBLANK(TRUE),"",'DEAL LOG'!I16) | D7: =IF(#REF!=ISBLANK(TRUE),"",#REF!) -> #REF! | E7: =IF('DEAL LOG'!K16=ISBLANK(TRUE),"",'DEAL LOG'!K16) -> New | F7: =IF('DEAL LOG'!L16=ISBLANK(TRUE),"",'DEAL LOG'!L16) -> 2026 | G7: =IF('DEAL LOG'!M16=ISBLANK(TRUE),"",'DEAL LOG'!M16) -> HONDA | H7: =IF('DEAL LOG'!N16=ISBLANK(TRUE),"",'DEAL LOG'!N16) -> HR-V | I7: =IF('DEAL LOG'!Y16=ISBLANK(TRUE),"",'DEAL LOG'!Y16) -> 0 | J7: =I7*0.25 -> 0 | K7: =IF(M7<1,"Yes","No") -> Yes | L7: =IF('DEAL LOG'!W16=ISBLANK(TRUE),"",'DEAL LOG'!W16) -> MAYCON MIKE GUIMARAES | M7: 0.5 | N7: =J7*M7 -> 0 | O7: =IF('DEAL LOG'!X16=ISBLANK(TRUE),"",'DEAL LOG'!X16) | P7: 0.5 | Q7: =J7*P7 -> 0
A8: 1 | B8: =IF('DEAL LOG'!H15=ISBLANK(TRUE),"",'DEAL LOG'!H15) -> C20879 | C8: =IF('DEAL LOG'!$I$9=ISBLANK(TRUE),"",'DEAL LOG'!I15) | D8: =IF(#REF!=ISBLANK(TRUE),"",#REF!) -> #REF! | E8: =IF('DEAL LOG'!K15=ISBLANK(TRUE),"",'DEAL LOG'!K15) -> New | F8: =IF('DEAL LOG'!L15=ISBLANK(TRUE),"",'DEAL LOG'!L15) -> 2026 | G8: =IF('DEAL LOG'!M15=ISBLANK(TRUE),"",'DEAL LOG'!M15) -> HONDA | H8: =IF('DEAL LOG'!N15=ISBLANK(TRUE),"",'DEAL LOG'!N15) -> CIVIC | I8: =IF('DEAL LOG'!Y15=ISBLANK(TRUE),"",'DEAL LOG'!Y15) -> 5723.22 | J8: =I8*0.25 -> 1430.805 | K8: =IF(M8<1,"Yes","No") -> No | L8: =IF('DEAL LOG'!W15=ISBLANK(TRUE),"",'DEAL LOG'!W15) -> JOSE TORRES | M8: 1 | N8: =J8*M8 -> 1430.805 | O8: =IF('DEAL LOG'!X15=ISBLANK(TRUE),"",'DEAL LOG'!X15) | P8: =IF(#REF!=ISBLANK(TRUE),"",#REF!) -> #REF! | Q8: =J8*P8 -> #REF!
A9: 1 | B9: =IF(#REF!=ISBLANK(TRUE),"",#REF!) -> #REF! | C9: =IF('DEAL LOG'!$I$9=ISBLANK(TRUE),"",#REF!) | D9: =IF(#REF!=ISBLANK(TRUE),"",#REF!) -> #REF! | E9: =IF(#REF!=ISBLANK(TRUE),"",#REF!) -> #REF! | F9: =IF(#REF!=ISBLANK(TRUE),"",#REF!) -> #REF! | G9: =IF(#REF!=ISBLANK(TRUE),"",#REF!) -> #REF! | H9: =IF(#REF!=ISBLANK(TRUE),"",#REF!) -> #REF! | I9: =IF(#REF!=ISBLANK(TRUE),"",#REF!) -> #REF! | J9: =I9*0.25 -> #REF! | K9: =IF(M9<1,"Yes","No") -> No | L9: =IF(#REF!=ISBLANK(TRUE),"",#REF!) -> #REF! | M9: 1 | N9: =J9*M9 -> #REF! | O9: =IF(#REF!=ISBLANK(TRUE),"",#REF!) -> #REF! | P9: =IF(#REF!=ISBLANK(TRUE),"",#REF!) -> #REF! | Q9: =J9*P9 -> #REF!
A10: 1 | B10: =IF(#REF!=ISBLANK(TRUE),"",#REF!) -> #REF! | C10: =IF('DEAL LOG'!$I$9=ISBLANK(TRUE),"",#REF!) | D10: =IF(#REF!=ISBLANK(TRUE),"",#REF!) -> #REF! | E10: =IF(#REF!=ISBLANK(TRUE),"",#REF!) -> #REF! | F10: =IF(#REF!=ISBLANK(TRUE),"",#REF!) -> #REF! | G10: =IF(#REF!=ISBLANK(TRUE),"",#REF!) -> #REF! | H10: =IF(#REF!=ISBLANK(TRUE),"",#REF!) -> #REF! | I10: =IF(#REF!=ISBLANK(TRUE),"",#REF!) -> #REF! | J10: =I10*0.25 -> #REF! | K10: =IF(M10<1,"Yes","No") -> No | L10: =IF(#REF!=ISBLANK(TRUE),"",#REF!) -> #REF! | M10: 1 | N10: =J10*M10 -> #REF! | O10: =IF(#REF!=ISBLANK(TRUE),"",#REF!) -> #REF! | P10: =IF(#REF!=ISBLANK(TRUE),"",#REF!) -> #REF! | Q10: =J10*P10 -> #REF!
